Workbook

Sheet 设备管理
A1: 设备管理
A2: 序号 | B2: 名称及型号 | C2: 编号 | D2: 状态 | E2: 利用率
A3: 1 | B3: 火花源原子发射光谱仪SPECTRO MAXx | C3: ALTCCS-2022001 | D3: 运行 | E3: 0.3
A4: 2 | B4: 全自动显微维氏硬度计THVS-1MDX-AXYZF | C4: ALTCCS-2022005 | D4: 运行 | E4: 0.2
A5: 3 | B5: 布氏硬度计 THB-3000S | C5: ALTCCS-2022006 | D5: 运行 | E5: 0.2
A6: 4 | B6: 洛氏硬度计 THR-150DT | C6: ALTCCS-2022008 | D6: 运行 | E6: 0.2
A7: 5 | B7: 金相显微镜 AE2000MET | C7: ALTCCS-2022013 | D7: 运行 | E7: 0.3
A8: 6 | B8: 水平燃烧测试仪 TTech-GB8410-T | C8: ALTCCS-2022026 | D8: 运行 | E8: 0.2
A9: 7 | B9: 垂直燃烧测试仪 TTech-GB32086-T | C9: ALTCCS-2022027 | D9: 运行 | E9: 0.2
A10: 8 | B10: 盐雾试验箱（中性） QS-ST-720optA | C10: ALTCCS-2022035 | D10: 运行 | E10: 0.6
A11: 9 | B11: 2T电子万能试验机 CMT4204 | C11: ALTCCS-2022052 | D11: 运行 | E11: 0.5
A12: 10 | B12: 5T电子万能试验机 E45.504 | C12: ALTCCS-2022053 | D12: 运行 | E12: 0.5
A13: 11 | B13: 熔体流动速率试验机ZRE1452 | C13: ALTCCS-2022055 | D13: 运行 | E13: 0.3
A14: 12 | B14: 热变形维卡试验机 ZWK1302-B | C14: ALTCCS-2022056 | D14: 运行 | E14: 0.3
... A23: 21 | B23: 钢直尺 500mm | C23: ALTCCS-2022072 | D23: 运行 | E23: 0.5

Sheet 环境管理
A1: 环境管理
A2: 位置 | B2: 名称 | C2: 温度 | D2: 湿度
A3: 一层 | B3: 扫描电镜试验室 | C3: 25℃ | D3: RH50%
B4: 工业CT试验室 | C4: 24℃ | D4: RH50%
B5: 机械性能分析室1 | C5: 23℃ | D5: RH50%
B6: 配电房 | C6: 25℃ | D6: RH50%
B7: 消防阀室 | C7: 23℃ | D7: RH50%
B8: 特殊试剂室 | C8: 25℃ | D8: RH50%
B9: 机房1 | C9: 23℃ | D9: RH50%
A10: 二层 | B10: 样品拍照室 | C10: 25℃ | D10: RH50%
B11: 化学分析室 | C11: 23℃ | D11: RH50%
B12: 物理分析室 | C12: 25℃ | D12: RH50%
B13: 机械性能分析室2 | C13: 25℃ | D13: RH50%
B14: 老化性能分析室1 | C14: 23℃ | D14: RH50%
B15: 老化性能分析室2 | C15: 22℃ | D15: RH50%
B16: 腐蚀性能试验室2 | C16: 25℃ | D16: RH50%
B17: 腐蚀性能试验室3 | C17: 24℃ | D17: RH50%
B18: 金相制样室 | C18: 25℃ | D18: RH50%
B19: 形貌观察室 | C19: 25℃ | D19: RH50%
B20: 无损检测室 | C20: 25℃ | D20: RH50%
B21: 机房2 | C21: 21℃ | D21: RH50%
B22: 纯水站房 | C22: 25℃ | D22: RH50%
... B27: 会议室1 | C27: 25℃ | D27: RH50%
A28: 三层 | B28: 热性能分析室 | C28: 25℃ | D28: RH50%
B29: 环境友好分析室 | C29: 22℃ | D29: RH50%
B30: 燃烧性能分析室 | C30: 25℃ | D30: RH50%
B31: 电性能分析室 | C31: 23℃ | D31: RH50%
B32: VOC采样室2 | C32: 25℃ | D32: RH50%
B33: 试剂存储室 | C33: 22℃ | D33: RH50%
B34: 留样存储室2 | C34: 25℃ | D34: RH50%
B35: 样品加工室 | C35: 24℃ | D35: RH50%
B36: 会议室2 | C36: 25℃ | D36: RH50%
B37: 会议室3 | C37: 25℃ | D37: RH50%
B38: 培训室1 | C38: 22℃ | D38: RH50%
B39: 培训室2 | C39: 23℃ | D39: RH50%
B40: 新风机房 | C40: 25℃ | D40: RH50%
B41: 气瓶间 | C41: 24℃ | D41: RH50%

Sheet 易耗品管理
A1: 易耗品管理
A2: 物料编号 | B2: 名称 | C2: 规格型号 | D2: 单位 | E2: 累计入库 | F2: 累计出库 | G2: 当前库存 | H2: 类别 | I2: 库位
A3: 01001 | B3: 0-150℃温度计 | C3: 0-150℃ | D3: 个 | E3: 1 | F3: 1 | G3: =E3-F3 -> 0 | H3: 低值易耗品
A4: 01002 | B4: 0-300℃温度计 | C4: 0-300℃ | D4: 个 | E4: 1 | F4: 1 | G4: =E4-F4 -> 0 | H4: 低值易耗品
A5: 01003 | B5: 30cm钢直尺 | C5: 30cm | D5: 个 | E5: 5 | F5: 5 | G5: =E5-F5 -> 0 | H5: 低值易耗品
A6: 01004 | B6: 50cm钢直尺 | C6: 50cm | D6: 个 | E6: 1 | F6: 1 | G6: =E6-F6 -> 0 | H6: 低值易耗品
A7: 01005 | B7: 电子秒表 | C7: / | D7: 个 | E7: 1 | F7: 1 | G7: =E7-F7 -> 0 | H7: 低值易耗品
A8: 01006 | B8: 温湿度计 | C8: / | D8: 个 | E8: 8 | F8: 8 | G8: =E8-F8 -> 0 | H8: 低值易耗品
A9: 01007 | B9: 游标卡尺 | C9: 0-200mm | D9: 个 | E9: 1 | F9: 1 | G9: =E9-F9 -> 0 | H9: 低值易耗品
A10: 01008 | B10: 钢气瓶 | C10: 40L | D10: 个 | E10: =SUMIF([1]入库明细!C:C,B10,[1]入库明细!H:H) -> 12 | F10: =SUMIF([1]出库明细!C:C,B10,[1]出库明细!H:H) -> 12 | G10: =E10-F10 -> 0 | H10: 低值易耗品
A11: 01009 | B11: 丙烷气瓶 | C11: 15kg | D11: 个 | E11: =SUMIF([1]入库明细!C:C,B11,[1]入库明细!H:H) -> 1 | F11: =SUMIF([1]出库明细!C:C,B11,[1]出库明细!H:H) -> 1 | G11: =E11-F11 -> 0 | H11: 低值易耗品
A12: 01010 | B12: 液化石油气罐 | C12: 5kg | D12: 个 | E12: =SUMIF([1]入库明细!C:C,B12,[1]入库明细!H:H) -> 1 | F12: =SUMIF([1]出库明细!C:C,B12,[1]出库明细!H:H) -> 1 | G12: =E12-F12 -> 0 | H12: 低值易耗品
A13: 01011 | B13: 维氏硬度块 | C13: HV1 | D13: 块 | E13: =SUMIF([1]入库明细!C:C,B13,[1]入库明细!H:H) -> 1 | F13: =SUMIF([1]出库明细!C:C,B13,[1]出库明细!H:H) -> 1 | G13: =E13-F13 -> 0 | H13: 低值易耗品
A14: 01012 | B14: 镊子 | C14: 直头、平头、弯头 | D14: 套 | E14: =SUMIF([1]入库明细!C:C,B14,[1]入库明细!H:H) -> 2 | F14: =SUMIF([1]出库明细!C:C,B14,[1]出库明细!H:H) -> 1 | G14: =E14-F14 -> 1 | H14: 低值易耗品 | I14: C-4-1
A15: 01013 | B15: 重型订书机 | C15: 型号0396 | D15: 个 | E15: =SUMIF([1]入库明细!C:C,B15,[1]入库明细!H:H) -> 1 | F15: =SUMIF([1]出库明细!C:C,B15,[1]出库明细!H:H) -> 1 | G15: =E15-F15 -> 0 | H15: 低值易耗品
A16: 01014 | B16: 手推车 | C16: 110*65 | D16: 个 | E16: =SUMIF([1]入库明细!C:C,B16,[1]入库明细!H:H) -> 1 | F16: =SUMIF([1]出库明细!C:C,B16,[1]出库明细!H:H) -> 1 | G16: =E16-F16 -> 0 | H16: 低值易耗品
A17: 01015 | B17: 气瓶推车 | C17: 蓝色经典款普厚（1.0） | D17: 个 | E17: =SUMIF([1]入库明细!C:C,B17,[1]入库明细!H:H) -> 2 | F17: =SUMIF([1]出库明细!C:C,B17,[1]出库明细!H:H) -> 2 | G17: =E17-F17 -> 0 | H17: 低值易耗品
A18: 01016 | B18: 吹风机 | C18: / | D18: 个 | E18: =SUMIF([1]入库明细!C:C,B18,[1]入库明细!H:H) -> 1 | F18: =SUMIF([1]出库明细!C:C,B18,[1]出库明细!H:H) -> 1 | G18: =E18-F18 -> 0 | H18: 低值易耗品
A19: 01017 | B19: 垫脚 | C19: / | D19: 个 | E19: =SUMIF([1]入库明细!C:C,B19,[1]入库明细!H:H) -> 4 | F19: =SUMIF([1]出库明细!C:C,B19,[1]出库明细!H:H) -> 4 | G19: =E19-F19 -> 0 | H19: 低值易耗品
A20: 01018 | B20: 白板 | C20: / | D20: 个 | E20: =SUMIF([1]入库明细!C:C,B20,[1]入库明细!H:H) -> 2 | F20: =SUMIF([1]出库明细!C:C,B20,[1]出库明细!H:H) -> 2 | G20: =E20-F20 -> 0 | H20: 低值易耗品
A21: 02001 | B21: 液压器油 | C21: 46号 | D21: 公斤 | E21: =SUMIF([1]入库明细!C:C,B21,[1]入库明细!H:H) -> 246.91 | F21: =SUMIF([1]出库明细!C:C,B21,[1]出库明细!H:H) -> 246.91 | G21: =E21-F21 -> 0 | H21: 原材料
A22: 02002 | B22: 氩气 | C22: 0.99 | D22: 40L | E22: =SUMIF([1]入库明细!C:C,B22,[1]入库明细!H:H) -> 4 | F22: =SUMIF([1]出库明细!C:C,B22,[1]出库明细!H:H) -> 4 | G22: =E22-F22 -> 0 | H22: 原材料
A23: 02003 | B23: 氮气 | C23: 0.99 | D23: 40L | E23: =SUMIF([1]入库明细!C:C,B23,[1]入库明细!H:H) -> 5 | F23: =SUMIF([1]出库明细!C:C,B23,[1]出库明细!H:H) -> 5 | G23: =E23-F23 -> 0 | H23: 原材料
A24: 02004 | B24: 氧气 | C24: 0.99 | D24: 40L | E24: =SUMIF([1]入库明细!C:C,B24,[1]入库明细!H:H) -> 2 | F24: =SUMIF([1]出库明细!C:C,B24,[1]出库明细!H:H) -> 2 | G24: =E24-F24 -> 0 | H24: 原材料
A25: 02005 | B25: 丙烷气 | C25: 0.95 | D25: 瓶 | E25: =SUMIF([1]入库明细!C:C,B25,[1]入库明细!H:H) -> 1 | F25: =SUMIF([1]出库明细!C:C,B25,[1]出库明细!H:H) -> 1 | G25: =E25-F25 -> 0 | H25: 原材料
A26: 02006 | B26: 液化石油气 | C26: / | D26: 5kg | E26: =SUMIF([1]入库明细!C:C,B26,[1]入库明细!H:H) -> 1 | F26: =SUMIF([1]出库明细!C:C,B26,[1]出库明细!H:H) -> 1 | G26: =E26-F26 -> 0 | H26: 原材料
A27: 02007 | B27: 岩谷丁烷气体 | C27: 0.95 | D27: 瓶 | E27: =SUMIF([1]入库明细!C:C,B27,[1]入库明细!H:H) -> 4 | F27: =SUMIF([1]出库明细!C:C,B27,[1]出库明细!H:H) -> 4 | G27: =E27-F27 -> 0 | H27: 原材料
A28: 02008 | B28: 滤纸60*60cm 中速 | C28: 60*60cm 中速 | D28: 包 | E28: =SUMIF([1]入库明细!C:C,B28,[1]入库明细!H:H) -> 2 | F28: =SUMIF([1]出库明细!C:C,B28,[1]出库明细!H:H) -> 2 | G28: =E28-F28 -> 0 | H28: 原材料
A29: 02009 | B29: 烧杯50ml | C29: 50ml | D29: 个 | E29: =SUMIF([1]入库明细!C:C,B29,[1]入库明细!H:H) -> 5 | F29: =SUMIF([1]出库明细!C:C,B29,[1]出库明细!H:H) -> 5 | G29: =E29-F29 -> 0 | H29: 原材料
A30: 02010 | B30: 烧杯100ml | C30: 100ml | D30: 个 | E30: =SUMIF([1]入库明细!C:C,B30,[1]入库明细!H:H) -> 5 | F30: =SUMIF([1]出库明细!C:C,B30,[1]出库明细!H:H) -> 5 | G30: =E30-F30 -> 0 | H30: 原材料
A31: 02011 | B31: 烧杯200ml | C31: 200ml | D31: 个 | E31: =SUMIF([1]入库明细!C:C,B31,[1]入库明细!H:H) -> 5 | F31: =SUMIF([1]出库明细!C:C,B31,[1]出库明细!H:H) -> 5 | G31: =E31-F31 -> 0 | H31: 原材料
A32: 02012 | B32: 烧杯500ml | C32: 500ml | D32: 个 | E32: =SUMIF([1]入库明细!C:C,B32,[1]入库明细!H:H) -> 5 | F32: =SUMIF([1]出库明细!C:C,B32,[1]出库明细!H:H) -> 5 | G32: =E32-F32 -> 0 | H32: 原材料
A33: 02013 | B33: 烧杯1000ml | C33: 1000ml | D33: 个 | E33: =SUMIF([1]入库明细!C:C,B33,[1]入库明细!H:H) -> 5 | F33: =SUMIF([1]出库明细!C:C,B33,[1]出库明细!H:H) -> 5 | G33: =E33-F33 -> 0 | H33: 原材料
A34: 02014 | B34: 容量瓶50ml | C34: 50ml | D34: 个 | E34: =SUMIF([1]入库明细!C:C,B34,[1]入库明细!H:H) -> 4 | F34: =SUMIF([1]出库明细!C:C,B34,[1]出库明细!H:H) -> 4 | G34: =E34-F34 -> 0 | H34: 原材料
A35: 02015 | B35: 容量瓶100ml | C35: 100ml | D35: 个 | E35: =SUMIF([1]入库明细!C:C,B35,[1]入库明细!H:H) -> 10 | F35: =SUMIF([1]出库明细!C:C,B35,[1]出库明细!H:H) -> 10 | G35: =E35-F35 -> 0 | H35: 原材料
A36: 02016 | B36: 容量瓶250ml | C36: 250ml | D36: 个 | E36: =SUMIF([1]入库明细!C:C,B36,[1]入库明细!H:H) -> 12 | F36: =SUMIF([1]出库明细!C:C,B36,[1]出库明细!H:H) -> 12 | G36: =E36-F36 -> 0 | H36: 原材料
A37: 02017 | B37: 容量瓶500ml | C37: 500ml | D37: 个 | E37: =SUMIF([1]入库明细!C:C,B37,[1]入库明细!H:H) -> 4 | F37: =SUMIF([1]出库明细!C:C,B37,[1]出库明细!H:H) -> 4 | G37: =E37-F37 -> 0 | H37: 原材料
A38: 02018 | B38: 容量瓶1000ml | C38: 1000ml | D38: 个 | E38: =SUMIF([1]入库明细!C:C,B38,[1]入库明细!H:H) -> 4 | F38: =SUMIF([1]出库明细!C:C,B38,[1]出库明细!H:H) -> 4 | G38: =E38-F38 -> 0 | H38: 原材料
A39: 02019 | B39: 容量瓶2000ml | C39: 2000ml | D39: 个 | E39: =SUMIF([1]入库明细!C:C,B39,[1]入库明细!H:H) -> 4 | F39: =SUMIF([1]出库明细!C:C,B39,[1]出库明细!H:H) -> 4 | G39: =E39-F39 -> 0 | H39: 原材料
... A49: 02029 | B49: 玻璃搅拌棒6mm*150mm | C49: 6mm*150mm | D49: 根 | E49: =SUMIF([1]入库明细!C:C,B49,[1]入库明细!H:H) -> 5 | F49: =SUMIF([1]出库明细!C:C,B49,[1]出库明细!H:H) -> 5 | G49: =E49-F49 -> 0 | H49: 原材料
...

Sheet 方法管理
A1: 方法管理
A2: 序号 | B2: 标准名称 | C2: 标准编号 | D2: 标准有效性 | E2: 备注
A3: 1 | B3: 金属显微组织检验方法 | C3: GB/T 13298-2015 | D3: þ现行有效 ¨作 废 | E3: CNAS
A4: 2 | B4: 钢的游离渗碳体、珠光体和魏氏组织的评定方法 | C4: GB/T 13299-2022 | D4: þ现行有效 ¨作 废 | E4: CNAS
A5: 3 | B5: 灰铸铁金相检验 | C5: GB/T 7216-2023 | D5: þ现行有效 ¨作 废 | E5: CNAS
A6: 4 | B6: 球墨铸铁金相检验 | C6: GB/T 9441-2021 | D6: þ现行有效 ¨作 废 | E6: CNAS
A7: 5 | B7: 钢中非金属夹杂物含量的测定 标准评级图显微检验法 | C7: GB/T 10561-2005 | D7: þ现行有效 ¨作 废 | E7: CNAS
A8: 6 | B8: 金属平均晶粒度测定方法 | C8: GB/T 6394-2017 | D8: þ现行有效 ¨作 废 | E8: CNAS
A9: 7 | B9: 低碳钢冷轧薄板铁素体晶粒度测定法 | C9: GB/T 4335-2013 | D9: þ现行有效 ¨作 废 | E9: CNAS
A10: 8 | B10: 金属材料焊缝破坏性试验 焊缝宏观和微观检验 | C10: GB/T 26955-2011 | D10: þ现行有效 ¨作 废 | E10: CNAS
A11: 9 | B11: 钢铁零件渗氮层深度测定和金相组织检验 | C11: GB/T 11354-2005 | D11: þ现行有效 ¨作 废 | E11: CNAS
A12: 10 | B12: 钢的脱碳层深度测定法 | C12: GB/T 224-2019 | D12: þ现行有效 ¨作 废 | E12: CNAS
A13: 11 | B13: 钢件渗碳淬火硬化层深度的测定和校核 | C13: GB/T 9450-2005 | D13: þ现行有效 ¨作 废 | E13: CNAS
A14: 12 | B14: 金属材料 布氏硬度试验 第1部分：试验方法 | C14: GB/T 231.1-2018 | D14: þ现行有效 ¨作 废 | E14: CNAS
... A37: 35 | B37: 汽车内饰材料的燃烧特性 | C37: GB 8410-2006 | D37: þ现行有效 ¨作 废 | E37: CNAS

Sheet 委托信息
A1: 委托信息
A2: 序号 | B2: 委托编号 | C2: 检测报告编号 | D2: 送样时间 | E2: 试验时间 | F2: 样件名称 | G2: 试验项目 | H2: 跟单人
A3: 1 | B3: 202211001 | C3: w-2022-ALTC-TC-001 | D3: 22.11.08 | E3: 22.11.09 | F3: 热轧板 | G3: 金属拉伸、弯曲 | H3: 吴凡
A4: 2 | B4: 202211002 | C4: w-2022-ALTC-TC-002 | D4: 22.11.21 | E4: 22.11.22 | F4: 聚丙烯 | G4: 塑料机械、热性能的测定 塑料拉伸、弯曲、冲击、负荷变形温度、维卡软化温度、熔体体流动速率 | H4: 吴凡
A5: 3 | B5: 202211003 | C5: w-2022-ALTC-TC-003 | D5: 22.11.28 | E5: 22.11.29 | F5: 橡胶 | G5: 橡胶拉伸、撕裂 | H5: 吴凡
A6: 4 | B6: 202212001 | C6: w-2022-ALTC-TC-004 | D6: 22.12.06 | E6: 22.12.07 | F6: 聚丙烯 | G6: 塑料机械、热性能的测定 塑料拉伸、弯曲、冲击、负荷变形温度、维卡软化温度、熔体体流动速率 | H6: 吴凡
A7: 5 | B7: 202212002 | C7: w-2022-ALTC-TC-005 | D7: 22.12.13 | E7: 22.12.14 | F7: 热轧板 | G7: 金属拉伸、弯曲 | H7: 吴凡
A8: 6 | B8: 202212003 | C8: w-2022-ALTC-TC-006 | D8: 22.12.19 | E8: 22.12.20 | F8: 橡胶 | G8: 橡胶拉伸、撕裂 | H8: 吴凡
A9: 7 | B9: 202301001 | C9: w-2023-ALTC-TC-001 | D9: 23.1.04 | E9: 23.1.05 | F9: 聚丙烯 | G9: 塑料机械、热性能的测定 塑料拉伸、弯曲、冲击、负荷变形温度、维卡软化温度、熔体体流动速率 | H9: 吴凡
A10: 8 | B10: 202301002 | C10: w-2023-ALTC-TC-002 | D10: 23.1.09 | E10: 23.1.10 | F10: 热轧板 | G10: 金属拉伸、弯曲 | H10: 吴凡
A11: 9 | B11: 202301003 | C11: w-2023-ALTC-TC-003 | D11: 23.1.11 | E11: 23.1.12 | F11: 橡胶 | G11: 橡胶拉伸、撕裂 | H11: 吴凡
A12: 10 | B12: 202302001 | C12: w-2023-ALTC-TC-004 | D12: 23.2.06 | E12: 23.2.07 | F12: 聚丙烯 | G12: 塑料机械、热性能的测定 塑料拉伸、弯曲、冲击、负荷变形温度、维卡软化温度、熔体体流动速率 | H12: 吴凡
A13: 11 | B13: 202302002 | C13: w-2023-ALTC-TC-005 | D13: 23.2.13 | E13: 23.2.14 | F13: 橡胶 | G13: 橡胶拉伸、撕裂 | H13: 吴凡
A14: 12 | B14: 202302003 | C14: w-2023-ALTC-TC-006 | D14: 23.2.20 | E14: 23.2.21 | F14: 热轧板 | G14: 金属拉伸、弯曲 | H14: 吴凡
... A25: 23 | B25: 202304008 | C25: w-2023-ALTC-TC-017 | D25: 23.4.17 | E25: 23.4.18 | F25: 橡胶 | G25: 橡胶拉伸、撕裂 | H25: 吴凡
A26: 24 | B26: 202304009 | D26: 23.4.18 | E26: 23.4.19 | F26: 横向稳定杆 | G26: 脱碳层深度、化学成分、洛氏硬度 | H26: 张鑫明
A27: 25 | B27: 202304010 | C27: w-2023-ALTC-TC-019 | D27: 23.4.18 | E27: 23.4.20 | F27: 聚丙烯 | G27: 塑料燃烧性能 水平燃烧、垂直燃烧、内饰燃烧 | H27: 吴凡
A28: 26 | B28: 202304011 | C28: w-2023-ALTC-TC-020 | D28: 23.4.21 | E28: 23.4.24 | F28: 后处理器壳体 | G28: 化学成分 | H28: 张鑫明
A29: 27 | B29: 202304012 | C29: w-2023-ALTC-TC-021 | D29: 23.4.25 | E29: 23.4.27 | F29: 进气接管 | G29: 化学成分 | H29: 张鑫明
A30: 28 | B30: 202304013 | C30: w-2023-ALTC-TC-022 | D30: 23.4.26 | E30: 23.4.27 | F30: 挡泥板支架 | G30: 化学成分 | H30: 张鑫明
A31: 29 | B31: 202304014 | C31: w-2023-ALTC-TC-023 | D31: 23.4.26 | E31: 23.4.27 | F31: 高压油管 | G31: 金相组织 | H31: 张鑫明
A32: 30 | B32: 202304015 | C32: w-2023-ALTC-TC-024 | D32: 23.4.27 | E32: 23.4.28 | F32: 油箱箍带 | G32: 金相组织 | H32: 张鑫明
A33: 31 | B33: 202305001 | C33: w-2023-ALTC-TC-025 | D33: 23.5.4 | E33: 23.5.8 | F33: 差动阀支架 | G33: 中性盐雾 | H33: 刘丽愉
A34: 32 | B34: 202305002 | C34: w-2023-ALTC-TC-026 | D34: 23.5.4 | E34: 23.5.5 | F34: 气室支架 | G34: 金相组织、硬度 | H34: 张鑫明
A35: 33 | B35: 202305003 | C35: w-2023-ALTC-TC-027 | D35: 23.5.5 | E35: 23.5.8 | F35: 调温器壳体 | G35: 化学成分 | H35: 张鑫明
A36: 34 | B36: 202305004 | C36: w-2023-ALTC-TC-028 | D36: 23.5.8 | E36: 23.5.9 | F36: 空气钢管支架 | G36: 金相组织 | H36: 张鑫明
A37: 35 | B37: 202305005 | C37: w-2023-ALTC-TC-029 | D37: 23.5.8 | E37: 23.5.9 | F37: 聚丙烯 | G37: 塑料机械、热性能的测定 塑料拉伸、弯曲、冲击、负荷变形温度、维卡软化温度、熔体体流动速率 | H37: 吴凡
A38: 36 | B38: 202305006 | C38: w-2023-ALTC-TC-030 | D38: 23.5.8 | E38: 23.5.9 | F38: 空气钢管 | G38: 金相组织 | H38: 张鑫明
... A53: 51 | B53: 202305021 | C53: w-2023-ALTC-TC-045 | D53: 23.5.26 | E53: 23.5.29 | F53: 聚丙烯（燃烧） | G53: 汽车内饰燃烧、垂直燃烧 | H53: 吴凡
A54: 52 | B54: 202305022 | C54: w-2023-ALTC-TC-046 | D54: 23.5.29 | E54: 23.5.30 | F54: 室温拉伸比对设备比对（5月）没出报告 | H54: 吴凡
A55: 53 | B55: 202306001 | C55: w-2023-ALTC-TC-047 | D55: 23.6.2 | E55: 23.6.3 | F55: 油箱箍带 | G55: 金相组织 | H55: 张鑫明
A56: 54 | B56: 202306002 | C56: w-2023-ALTC-TC-048 | D56: 23.6.6 | E56: 23.6.7 | F56: 雨刮连杆 | G56: 金相组织、化学成分 | H56: 张鑫明
A57: 55 | B57: 202306003 | C57: w-2023-ALTC-TC-049 | D57: 23.6.12 | E57: 23.6.13 | F57: 制动鼓 | G57: 金相组织 | H57: 张鑫明
A58: 56 | B58: 202306004 | C58: w-2023-ALTC-TC-050 | D58: 23.6.19 | E58: 23.6.20 | F58: 聚丙烯塑料 | G58: 塑料拉伸、熔体 | H58: 吴凡
A59: 57 | B59: 202306005 | C59: w-2023-ALTC-TC-051 | D59: 23.6.20 | E59: 23.6.21 | F59: 半轴 | G59: 脱碳层深度 | H59: 张鑫明
A60: 58 | B60: 202306006 | C60: w-2023-ALTC-TC-052 | D60: 23.6.22 | E60: 23.6.23 | F60: 热变形温度留样再测（6月）没出报告 | H60: 吴凡
A61: 59 | B61: 202306007 | C61: w-2023-ALTC-TC-053 | D61: 23.6.25 | E61: 23.6.26 | F61: 惰齿轮 | G61: 渗碳淬火硬化层深度测定 | H61: 张鑫明
A62: 60 | B62: 202306008 | C62: w-2023-ALTC-TC-054 | D62: 23.6.25 | E62: 23.6.26 | F62: 橡胶 | G62: 橡胶拉伸 | H62: 吴凡
A63: 61 | B63: 202306009 | C63: w-2023-ALTC-TC-055 | D63: 2023.6.26 | E63: 2023.6.27 | F63: 转向节 | G63: 金相组织 | H63: 张鑫明
A64: 62 | B64: 202306010 | C64: w-2023-ALTC-TC-056 | D64: 23.6.30 | E64: 23.7.3 | F64: 铝合金油箱 | G64: 化学成分 | H64: 张鑫明
...

Sheet Sheet2
A1: 时间 | B1: 任务量 | C1: 报告完成
A2: 8月 | B2: 12 | C2: 12
A3: 9月 | B3: 15 | C3: 15
A4: 10月 | B4: 26 | C4: 26
A5: 11月
A6: 12月
A17: 时间 | B17: 金额（万）
A18: 8月 | B18: 0
A19: 9月 | B19: 0
A20: 10月 | B20: 100
A21: 11月 | B21: 200
A22: 12月
